2024-10-17 15:50:39,722 INFO    MainThread:73044 [wandb_setup.py:_flush():79] Current SDK version is 0.18.3
2024-10-17 15:50:39,722 INFO    MainThread:73044 [wandb_setup.py:_flush():79] Configure stats pid to 73044
2024-10-17 15:50:39,722 INFO    MainThread:73044 [wandb_setup.py:_flush():79] Loading settings from /home/hgj/.config/wandb/settings
2024-10-17 15:50:39,722 INFO    MainThread:73044 [wandb_setup.py:_flush():79] Loading settings from /home/hgj/SDM274/HA-03&04_Classification_and_Logistic_Regression/wandb/settings
2024-10-17 15:50:39,722 INFO    MainThread:73044 [wandb_setup.py:_flush():79] Loading settings from environment variables: {}
2024-10-17 15:50:39,722 INFO    MainThread:73044 [wandb_setup.py:_flush():79] Applying setup settings: {'mode': None, '_disable_service': None}
2024-10-17 15:50:39,722 INFO    MainThread:73044 [wandb_setup.py:_flush():79] Inferring run settings from compute environment: {'program_relpath': 'HA-03&04_Classification_and_Logistic_Regression/train.py', 'program_abspath': '/home/hgj/SDM274/HA-03&04_Classification_and_Logistic_Regression/train.py', 'program': './train.py'}
2024-10-17 15:50:39,722 INFO    MainThread:73044 [wandb_setup.py:_flush():79] Applying login settings: {}
2024-10-17 15:50:39,722 INFO    MainThread:73044 [wandb_init.py:_log_setup():532] Logging user logs to /home/hgj/SDM274/HA-03&04_Classification_and_Logistic_Regression/wandb/run-20241017_155039-36w5ndtw/logs/debug.log
2024-10-17 15:50:39,722 INFO    MainThread:73044 [wandb_init.py:_log_setup():533] Logging internal logs to /home/hgj/SDM274/HA-03&04_Classification_and_Logistic_Regression/wandb/run-20241017_155039-36w5ndtw/logs/debug-internal.log
2024-10-17 15:50:39,722 INFO    MainThread:73044 [wandb_init.py:init():617] calling init triggers
2024-10-17 15:50:39,722 INFO    MainThread:73044 [wandb_init.py:init():624] wandb.init called with sweep_config: {}
config: {'_metadata': ContainerMetadata(ref_type=typing.Any, object_type=<class 'dict'>, optional=True, key=None, flags={'struct': True}, flags_root=False, resolver_cache=defaultdict(<class 'dict'>, {'now': {('%Y-%m-%d',): '2024-10-17', ('%H-%M-%S',): '15-50-34'}}), key_type=typing.Any, element_type=typing.Any), '_parent': None, '_flags_cache': {'struct': True}, '_content': {'dataset_path': './data/wine.data', 'wandb_on_off': True, 'lr': 0.01, 'epoch': 9000, 'tol': 1e-05, 'gd': 'SGD', 'wandb': {'project': 'hw3', 'dir': './outputs'}}}
2024-10-17 15:50:39,722 INFO    MainThread:73044 [wandb_init.py:init():667] starting backend
2024-10-17 15:50:39,723 INFO    MainThread:73044 [wandb_init.py:init():671] sending inform_init request
2024-10-17 15:50:39,723 INFO    MainThread:73044 [backend.py:_multiprocessing_setup():104] multiprocessing start_methods=fork,spawn,forkserver, using: spawn
2024-10-17 15:50:39,723 INFO    MainThread:73044 [wandb_init.py:init():684] backend started and connected
2024-10-17 15:50:39,724 ERROR   MainThread:73044 [wandb_init.py:init():1262] error in wandb.init()
Traceback (most recent call last):
  File "/home/hgj/anaconda3/envs/sdm274/lib/python3.8/site-packages/wandb/sdk/wandb_init.py", line 1252, in init
    return wi.init()
  File "/home/hgj/anaconda3/envs/sdm274/lib/python3.8/site-packages/wandb/sdk/wandb_init.py", line 689, in init
    run = Run(
  File "/home/hgj/anaconda3/envs/sdm274/lib/python3.8/site-packages/wandb/sdk/wandb_run.py", line 601, in __init__
    self._init(
  File "/home/hgj/anaconda3/envs/sdm274/lib/python3.8/site-packages/wandb/sdk/wandb_run.py", line 721, in _init
    self._config._update(config, ignore_locked=True)
  File "/home/hgj/anaconda3/envs/sdm274/lib/python3.8/site-packages/wandb/sdk/wandb_config.py", line 180, in _update
    sanitized = self._sanitize_dict(
  File "/home/hgj/anaconda3/envs/sdm274/lib/python3.8/site-packages/wandb/sdk/wandb_config.py", line 267, in _sanitize_dict
    k, v = self._sanitize(k, v, allow_val_change)
  File "/home/hgj/anaconda3/envs/sdm274/lib/python3.8/site-packages/wandb/sdk/wandb_config.py", line 285, in _sanitize
    val = json_friendly_val(val)
  File "/home/hgj/anaconda3/envs/sdm274/lib/python3.8/site-packages/wandb/util.py", line 674, in json_friendly_val
    converted = asdict(val)
  File "/home/hgj/anaconda3/envs/sdm274/lib/python3.8/dataclasses.py", line 1073, in asdict
    return _asdict_inner(obj, dict_factory)
  File "/home/hgj/anaconda3/envs/sdm274/lib/python3.8/dataclasses.py", line 1080, in _asdict_inner
    value = _asdict_inner(getattr(obj, f.name), dict_factory)
  File "/home/hgj/anaconda3/envs/sdm274/lib/python3.8/dataclasses.py", line 1110, in _asdict_inner
    return type(obj)((_asdict_inner(k, dict_factory),
TypeError: first argument must be callable or None
2024-10-17 15:50:41,747 WARNING MsgRouterThr:73044 [router.py:message_loop():77] message_loop has been closed
2024-10-17 15:51:38,696 INFO    Thread-1  :73044 [retry.py:__call__():172] Retry attempt failed:
Traceback (most recent call last):
  File "/home/hgj/anaconda3/envs/sdm274/lib/python3.8/site-packages/urllib3/connection.py", line 199, in _new_conn
    sock = connection.create_connection(
  File "/home/hgj/anaconda3/envs/sdm274/lib/python3.8/site-packages/urllib3/util/connection.py", line 85, in create_connection
    raise err
  File "/home/hgj/anaconda3/envs/sdm274/lib/python3.8/site-packages/urllib3/util/connection.py", line 73, in create_connection
    sock.connect(sa)
socket.timeout: timed out

The above exception was the direct cause of the following exception:

Traceback (most recent call last):
  File "/home/hgj/anaconda3/envs/sdm274/lib/python3.8/site-packages/urllib3/connectionpool.py", line 789, in urlopen
    response = self._make_request(
  File "/home/hgj/anaconda3/envs/sdm274/lib/python3.8/site-packages/urllib3/connectionpool.py", line 490, in _make_request
    raise new_e
  File "/home/hgj/anaconda3/envs/sdm274/lib/python3.8/site-packages/urllib3/connectionpool.py", line 466, in _make_request
    self._validate_conn(conn)
  File "/home/hgj/anaconda3/envs/sdm274/lib/python3.8/site-packages/urllib3/connectionpool.py", line 1095, in _validate_conn
    conn.connect()
  File "/home/hgj/anaconda3/envs/sdm274/lib/python3.8/site-packages/urllib3/connection.py", line 693, in connect
    self.sock = sock = self._new_conn()
  File "/home/hgj/anaconda3/envs/sdm274/lib/python3.8/site-packages/urllib3/connection.py", line 208, in _new_conn
    raise ConnectTimeoutError(
urllib3.exceptions.ConnectTimeoutError: (<urllib3.connection.HTTPSConnection object at 0x7f5fe8c054c0>, 'Connection to api.wandb.ai timed out. (connect timeout=20)')

The above exception was the direct cause of the following exception:

Traceback (most recent call last):
  File "/home/hgj/anaconda3/envs/sdm274/lib/python3.8/site-packages/requests/adapters.py", line 667, in send
    resp = conn.urlopen(
  File "/home/hgj/anaconda3/envs/sdm274/lib/python3.8/site-packages/urllib3/connectionpool.py", line 843, in urlopen
    retries = retries.increment(
  File "/home/hgj/anaconda3/envs/sdm274/lib/python3.8/site-packages/urllib3/util/retry.py", line 519, in increment
    raise MaxRetryError(_pool, url, reason) from reason  # type: ignore[arg-type]
urllib3.exceptions.MaxRetryError: HTTPSConnectionPool(host='api.wandb.ai', port=443): Max retries exceeded with url: /graphql (Caused by ConnectTimeoutError(<urllib3.connection.HTTPSConnection object at 0x7f5fe8c054c0>, 'Connection to api.wandb.ai timed out. (connect timeout=20)'))

During handling of the above exception, another exception occurred:

Traceback (most recent call last):
  File "/home/hgj/anaconda3/envs/sdm274/lib/python3.8/site-packages/wandb/sdk/lib/retry.py", line 131, in __call__
    result = self._call_fn(*args, **kwargs)
  File "/home/hgj/anaconda3/envs/sdm274/lib/python3.8/site-packages/wandb/sdk/internal/internal_api.py", line 347, in execute
    return self.client.execute(*args, **kwargs)  # type: ignore
  File "/home/hgj/anaconda3/envs/sdm274/lib/python3.8/site-packages/wandb/vendor/gql-0.2.0/wandb_gql/client.py", line 52, in execute
    result = self._get_result(document, *args, **kwargs)
  File "/home/hgj/anaconda3/envs/sdm274/lib/python3.8/site-packages/wandb/vendor/gql-0.2.0/wandb_gql/client.py", line 60, in _get_result
    return self.transport.execute(document, *args, **kwargs)
  File "/home/hgj/anaconda3/envs/sdm274/lib/python3.8/site-packages/wandb/sdk/lib/gql_request.py", line 58, in execute
    request = self.session.post(self.url, **post_args)
  File "/home/hgj/anaconda3/envs/sdm274/lib/python3.8/site-packages/requests/sessions.py", line 637, in post
    return self.request("POST", url, data=data, json=json, **kwargs)
  File "/home/hgj/anaconda3/envs/sdm274/lib/python3.8/site-packages/requests/sessions.py", line 589, in request
    resp = self.send(prep, **send_kwargs)
  File "/home/hgj/anaconda3/envs/sdm274/lib/python3.8/site-packages/requests/sessions.py", line 703, in send
    r = adapter.send(request, **kwargs)
  File "/home/hgj/anaconda3/envs/sdm274/lib/python3.8/site-packages/requests/adapters.py", line 688, in send
    raise ConnectTimeout(e, request=request)
requests.exceptions.ConnectTimeout: HTTPSConnectionPool(host='api.wandb.ai', port=443): Max retries exceeded with url: /graphql (Caused by ConnectTimeoutError(<urllib3.connection.HTTPSConnection object at 0x7f5fe8c054c0>, 'Connection to api.wandb.ai timed out. (connect timeout=20)'))
